Workbook

Sheet Inspection History
A1: Inspection History — Atomic Industries, 50479 Birch Drive, Shelby Township, MI
A2: One row per inspection, never overwritten. Add a row here, or use Walk mode in the dashboard, and every tab's Last date, Next date and status update from it. Only Pass rows count toward the schedule: a Fail stays on the record but does not reset the clock, so the device keeps coming due until it passes.
A3: Device must match the map (FE7, EW2, AED1) and Check must come from the dropdown. Rows dated before 10/26/2026 were carried over from the old log, which only ever kept each check's latest date, so history before then is partial.
A5: Date | B5: Device | C5: Check | D5: Result | E5: Inspected By | F5: Notes
A6: 46071 | B6: EL1 | C6: Annual Test | D6: Pass | F6: Carried over from the PM log as it stood 10/19/2026; inspector not recorded.
A7: 46071 | B7: EL2 | C7: Annual Test | D7: Pass | F7: Carried over from the PM log as it stood 10/19/2026; inspector not recorded.
A8: 46071 | B8: EL3 | C8: Annual Test | D8: Pass | F8: Carried over from the PM log as it stood 10/19/2026; inspector not recorded.
A9: 46071 | B9: EL4 | C9: Annual Test | D9: Pass | F9: Carried over from the PM log as it stood 10/19/2026; inspector not recorded.
A10: 46071 | B10: EL5 | C10: Annual Test | D10: Pass | F10: Carried over from the PM log as it stood 10/19/2026; inspector not recorded.
A11: 46071 | B11: EL6 | C11: Annual Test | D11: Pass | F11: Carried over from the PM log as it stood 10/19/2026; inspector not recorded.
A12: 46071 | B12: EL7 | C12: Annual Test | D12: Pass | F12: Carried over from the PM log as it stood 10/19/2026; inspector not recorded.
A13: 46071 | B13: EL8 | C13: Annual Test | D13: Pass | F13: Carried over from the PM log as it stood 10/19/2026; inspector not recorded.
A14: 46071 | B14: EL9 | C14: Annual Test | D14: Pass | F14: Carried over from the PM log as it stood 10/19/2026; inspector not recorded.
A15: 46071 | B15: EL10 | C15: Annual Test | D15: Pass | F15: Carried over from the PM log as it stood 10/19/2026; inspector not recorded.
A16: 46071 | B16: EL11 | C16: Annual Test | D16: Pass | F16: Carried over from the PM log as it stood 10/19/2026; inspector not recorded.
A17: 46071 | B17: EL12 | C17: Annual Test | D17: Pass | F17: Carried over from the PM log as it stood 10/19/2026; inspector not recorded.
... A36: 46082 | B36: FE8 | C36: Annual Maint | D36: Pass | F36: Annual service confirmed done at installation, March 2026.
A37: 46082 | B37: FE9 | C37: Annual Maint | D37: Pass | E37: UniFirst | F37: Carried over: UniFirst service tag, March 2026.
A38: 46082 | B38: FE10 | C38: Annual Maint | D38: Pass | E38: UniFirst | F38: Carried over: UniFirst service tag, March 2026.
A39: 46082 | B39: FE11 | C39: Annual Maint | D39: Pass | F39: Annual service confirmed done at installation, March 2026.
A40: 46082 | B40: FE12 | C40: Annual Maint | D40: Pass | E40: UniFirst | F40: Carried over: UniFirst service tag, March 2026.
A41: 46082 | B41: FE13 | C41: Annual Maint | D41: Pass | E41: UniFirst | F41: Carried over: UniFirst service tag, March 2026.
A42: 46082 | B42: FE14 | C42: Annual Maint | D42: Pass | E42: UniFirst | F42: Carried over: UniFirst service tag, March 2026.
A43: 46082 | B43: FE15 | C43: Annual Maint | D43: Pass | E43: UniFirst | F43: Carried over: UniFirst service tag, March 2026.
A44: 46082 | B44: FE16 | C44: Annual Maint | D44: Pass | E44: UniFirst | F44: Carried over: UniFirst service tag, March 2026.
A45: 46082 | B45: FE17 | C45: Annual Maint | D45: Pass | E45: UniFirst | F45: Carried over: UniFirst service tag, March 2026.
A46: 46082 | B46: FE18 | C46: Annual Maint | D46: Pass | E46: UniFirst | F46: Carried over: UniFirst service tag, March 2026.
A47: 46082 | B47: FE19 | C47: Annual Maint | D47: Pass | E47: UniFirst | F47: Carried over: UniFirst service tag, March 2026.
A48: 46082 | B48: FE20 | C48: Annual Maint | D48: Pass | E48: UniFirst | F48: Carried over: UniFirst service tag, March 2026.
A49: 46082 | B49: FE21 | C49: Annual Maint | D49: Pass | F49: Annual service confirmed done at installation, March 2026.
A50: 46174 | B50: EW2 | C50: Annual Inspection | D50: Pass | F50: Carried over. This was the squeeze-bottle station, replaced with a gravity-fed unit on 10/19/2026.
A51: 46174 | B51: EW2 | C51: Fluid Change | D51: Pass | F51: Carried over. This was the squeeze-bottle station, replaced with a gravity-fed unit on 10/19/2026.
A52: 46255 | B52: EW1 | C52: Annual Inspection | D52: Pass | F52: Carried over from the PM log as it stood 10/19/2026; inspector not recorded.
A53: 46255 | B53: EW3 | C53: Annual Inspection | D53: Pass | F53: Carried over from the PM log as it stood 10/19/2026; inspector not recorded.
A54: 46255 | B54: EW4 | C54: Annual Inspection | D54: Pass | F54: Carried over from the PM log as it stood 10/19/2026; inspector not recorded.
A55: 46295 | B55: FE1 | C55: Monthly Insp | D55: Pass | F55: Carried over from the PM log as it stood 10/19/2026; inspector not recorded.
A56: 46295 | B56: FE2 | C56: Monthly Insp | D56: Pass | F56: Carried over from the PM log as it stood 10/19/2026; inspector not recorded.
A57: 46295 | B57: FE3 | C57: Monthly Insp | D57: Pass | F57: Carried over from the PM log as it stood 10/19/2026; inspector not recorded.
A58: 46295 | B58: FE4 | C58: Monthly Insp | D58: Pass | F58: Carried over from the PM log as it stood 10/19/2026; inspector not recorded.
A59: 46295 | B59: FE5 | C59: Monthly Insp | D59: Pass | F59: Carried over from the PM log as it stood 10/19/2026; inspector not recorded.
...

Sheet Intervals
A1: Inspection Intervals — code reference and single source of truth
A2: All four log tabs read their intervals from this sheet. Change a number here and every affected due date moves with it. Yellow cells are the editable ones.
A3: Recurring checks
A4: Asset | B4: Check | C4: Every | D4: Unit | E4: Code reference
A5: Fire extinguisher | B5: Monthly inspection | C5: 30 | D5: days | E5: NFPA 10 — inspection at 30-day intervals; may be done in-house
A6: Fire extinguisher | B6: Annual maintenance | C6: 12 | D6: months | E6: NFPA 10 — annual maintenance by a certified technician
A7: Emergency light | B7: Monthly function test | C7: 30 | D7: days | E7: NFPA 101 7.9.3 — 30-day test, minimum 30 seconds
A8: Emergency light | B8: Annual full-duration test | C8: 12 | D8: months | E8: NFPA 101 7.9.3 — annual test, 90 minutes on battery
A9: Eye wash station | B9: Weekly activation / visual check | C9: 7 | D9: days | E9: ANSI/ISEA Z358.1 — weekly activation to clear the dead leg and confirm flow
A10: Eye wash station | B10: Annual inspection | C10: 12 | D10: months | E10: ANSI/ISEA Z358.1 — annual inspection by a competent person, full 15-minute flow
A12: Extinguisher type → internal examination and hydrostatic test intervals
A13: Extinguisher type | B13: Internal exam (years) | C13: Hydrostatic test (years) | D13: Code reference
A14: Dry chemical, stored pressure | B14: 6 | C14: 12 | D14: NFPA 10 — stored-pressure units on a 12-year hydro get a 6-year internal exam
A15: Dry chemical, stainless steel shell | B15: 5 | C15: 5 | D15: NFPA 10 — stainless shells hydro at 5 years
A16: Carbon dioxide (CO2) | B16: 5 | C16: 5 | D16: NFPA 10 — CO2 internal and hydro at 5 years
A17: Water / water mist | B17: 5 | C17: 5 | D17: NFPA 10 — pressurized water and water mist hydro at 5 years
A18: Wet chemical (Class K) | B18: 5 | C18: 5 | D18: NFPA 10 — wet chemical internal and hydro at 5 years
A20: Eye wash type → flushing-fluid replacement
A21: Eye wash type | B21: Fluid change (months) | C21: Note
A22: Plumbed | B22: 0 | C22: Fed from the water line — no flushing fluid to replace, so 0 = not applicable. The weekly check is a live activation.
A23: Self-contained (portable) | B23: 12 | C23: Gravity-fed tank — replace the flushing fluid on the manufacturer's schedule. 12 months is the common default; check the label, some require quarterly.
A24: Supplemental (squeeze bottles) | B24: 0 | C24: Sealed bottles carry their own printed expiry — there is no fluid to change, so the check reads N/A. Z358.1 treats bottles as supplemental only; they do not satisfy the 15-minute flush a plumbed or self-contained unit provides.
A25: Dashboard settings
A26: Warn "due soon" this many days ahead — monthly and annual checks | C26: 7
A27: Warn "due soon" this many days ahead — weekly checks | C27: 2
A28: A weekly check needs a shorter warning window than a monthly one — a 7-day warning on a 7-day interval would show amber every single day.
A30: Sources: NFPA 10 (portable fire extinguishers), NFPA 101 7.9.3 (emergency lighting) and ANSI/ISEA Z358.1 (emergency eyewash), as summarised by fireinspected.com, the Minnesota Department of Health Life Safety Code guidance, and Haws Co. Confirm the enforced edition before an inspection.
A32: AED — recurring check and consumable life (added 08/21/2026)
A33: Asset | B33: Check | C33: Every | D33: Unit | E33: Code reference
A34: AED | B34: Monthly readiness check | C34: 30 | D34: days | E34: No code sets an AED interval. OSHA 1910.151 (first aid) and the General Duty Clause apply; a documented monthly check of the status indicator, pads and rescue kit is the manufacturer/AHA practice. Michigan MCL 691.1504 is Good Samaritan immunity, not a maintenance mandate.
A35: AED | B35: Battery pack replacement | C35: 60 | D35: months | E35: ZOLL AED 3 — battery pack has up to a five-year installed standby life. The log takes the printed expiry as the input and works the install date back from it.
A36: AED | B36: Electrode pad replacement | C36: 60 | D36: months | E36: ZOLL CPR Uni-padz — five-year installed life, same handling as the battery. Replace after ANY use regardless of the printed date.
A38: Warn "due soon" this many days ahead — AED battery and pads | C38: 60
A39: Battery and pad replacements warn 60 days out, not 7: a pack has to be ordered, and an AED with expired consumables is not a working AED.

Sheet FE Log
A1: Fire Extinguisher PM Log — Atomic Industries, 50479 Birch Drive, Shelby Township, MI
A2: Dates come from the Inspection History tab: add a row there, or use Walk mode in the dashboard. Edit only the yellow cells. NFPA 10 requires four separate checks per extinguisher — a 30-day inspection, annual maintenance, an internal examination and a hydrostatic test. Status and Next Action always report whichever comes due first.
A3: Type confirmed from the collar-tag photos: 16 dry chemical and 5 CO2 (FE2, FE4, FE5, FE6, FE7). Internal exam and hydrostatic test have never been performed on these 2026 cylinders, so those columns are blank by design — both clocks run from Mfd Date (01/01/2026, the earliest the ZX26 stamp allows, so the dates are the conservative ones). Enter a real exam date and it overrides the fallback.
A5: FE # | B5: Near Location | C5: Type | D5: Last Monthly Insp | E5: Next Monthly Insp | F5: Last Annual Maint | G5: Next Annual Maint | H5: Last Internal Exam | I5: Next Internal Exam | J5: Last Hydro Test | K5: Next Hydro Test | L5: Next Action | M5: Days Remaining | N5: Status | O5: Notes | P5: Mfd Date | Q5: Last Inspected By
A6: FE1 | B6: Admin Desk / Office Area entrance | C6: Dry chemical, stored pressure | D6: =IF(_xlfn.MAXIFS('Inspection History'!$A$6:$A$20000,'Inspection History'!$B$6:$B$20000,$A6,'Inspection History'!$C$6:$C$20000,"Monthly Insp",'Inspection History'!$D$6:$D$20000,"Pass")=0,"",_xlfn.MAXIFS('Inspection History'!$A$6:$A$20000,'Inspection History'!$B$6:$B$20000,$A6,'Inspection History'!$C$6:$C$20000,"Monthly Insp",'Inspection History'!$D$6:$D$20000,"Pass")) -> 46321 | E6: =IF($D6="","",$D6+Intervals!$C$5) -> 46351 | F6: =IF(_xlfn.MAXIFS('Inspection History'!$A$6:$A$20000,'Inspection History'!$B$6:$B$20000,$A6,'Inspection History'!$C$6:$C$20000,"Annual Maint",'Inspection History'!$D$6:$D$20000,"Pass")=0,"",_xlfn.MAXIFS('Inspection History'!$A$6:$A$20000,'Inspection History'!$B$6:$B$20000,$A6,'Inspection History'!$C$6:$C$20000,"Annual Maint",'Inspection History'!$D$6:$D$20000,"Pass")) -> 46082 | G6: =IF($F6="","",EDATE($F6,Intervals!$C$6)) -> 46447 | H6: =IF(_xlfn.MAXIFS('Inspection History'!$A$6:$A$20000,'Inspection History'!$B$6:$B$20000,$A6,'Inspection History'!$C$6:$C$20000,"Internal Exam",'Inspection History'!$D$6:$D$20000,"Pass")=0,"",_xlfn.MAXIFS('Inspection History'!$A$6:$A$20000,'Inspection History'!$B$6:$B$20000,$A6,'Inspection History'!$C$6:$C$20000,"Internal Exam",'Inspection History'!$D$6:$D$20000,"Pass")) | I6: =IF(OR($C6="",AND($H6="",$P6="")),"",EDATE(IF($H6="",$P6,$H6),12*INDEX(Intervals!$B$14:$B$18,MATCH($C6,Intervals!$A$14:$A$18,0)))) -> 48214 | J6: =IF(_xlfn.MAXIFS('Inspection History'!$A$6:$A$20000,'Inspection History'!$B$6:$B$20000,$A6,'Inspection History'!$C$6:$C$20000,"Hydro Test",'Inspection History'!$D$6:$D$20000,"Pass")=0,"",_xlfn.MAXIFS('Inspection History'!$A$6:$A$20000,'Inspection History'!$B$6:$B$20000,$A6,'Inspection History'!$C$6:$C$20000,"Hydro Test",'Inspection History'!$D$6:$D$20000,"Pass")) | K6: =IF(OR($C6="",AND($J6="",$P6="")),"",EDATE(IF($J6="",$P6,$J6),12*INDEX(Intervals!$C$14:$C$18,MATCH($C6,Intervals!$A$14:$A$18,0)))) -> 50406 | L6: =IF(COUNT($E6,$G6,$I6,$K6)=0,"—",IF(MIN($E6,$G6,$I6,$K6)=$E6,"Monthly inspection",IF(MIN($E6,$G6,$I6,$K6)=$G6,"Annual maintenance",IF(MIN($E6,$G6,$I6,$K6)=$I6,"Internal exam","Hydrostatic test")))) -> Monthly inspection | M6: =IF(COUNT($E6,$G6,$I6,$K6)=0,"",MIN($E6,$G6,$I6,$K6)-TODAY()) -> 30 | N6: =IF($M6="","NOT LOGGED",IF($M6<=0,"OVERDUE",IF($M6<=Intervals!$C$26,"DUE SOON","OK"))) -> OK | P6: 46023 | Q6: =IF($D6="","",IF(SUMPRODUCT(MAX(('Inspection History'!$B$6:$B$20000=$A6)*('Inspection History'!$C$6:$C$20000="Monthly Insp")*('Inspection History'!$D$6:$D$20000="Pass")*('Inspection History'!$A$6:$A$20000=$D6)*ROW('Inspection History'!$A$6:$A$20000)))=0,"",INDEX('Inspection History'!$E:$E,SUMPRODUCT(MAX(('Inspection History'!$B$6:$B$20000=$A6)*('Inspection History'!$C$6:$C$20000="Monthly Insp")*('Inspection History'!$D$6:$D$20000="Pass")*('Inspection History'!$A$6:$A$20000=$D6)*ROW('Inspection History'!$A$6:$A$20000))))&"")) -> J. Godek
A7: FE2 | B7: IT Room hallway | C7: Carbon dioxide (CO2) | D7: =IF(_xlfn.MAXIFS('Inspection History'!$A$6:$A$20000,'Inspection History'!$B$6:$B$20000,$A7,'Inspection History'!$C$6:$C$20000,"Monthly Insp",'Inspection History'!$D$6:$D$20000,"Pass")=0,"",_xlfn.MAXIFS('Inspection History'!$A$6:$A$20000,'Inspection History'!$B$6:$B$20000,$A7,'Inspection History'!$C$6:$C$20000,"Monthly Insp",'Inspection History'!$D$6:$D$20000,"Pass")) -> 46321 | E7: =IF($D7="","",$D7+Intervals!$C$5) -> 46351 | F7: =IF(_xlfn.MAXIFS('Inspection History'!$A$6:$A$20000,'Inspection History'!$B$6:$B$20000,$A7,'Inspection History'!$C$6:$C$20000,"Annual Maint",'Inspection History'!$D$6:$D$20000,"Pass")=0,"",_xlfn.MAXIFS('Inspection History'!$A$6:$A$20000,'Inspection History'!$B$6:$B$20000,$A7,'Inspection History'!$C$6:$C$20000,"Annual Maint",'Inspection History'!$D$6:$D$20000,"Pass")) -> 46082 | G7: =IF($F7="","",EDATE($F7,Intervals!$C$6)) -> 46447 | H7: =IF(_xlfn.MAXIFS('Inspection History'!$A$6:$A$20000,'Inspection History'!$B$6:$B$20000,$A7,'Inspection History'!$C$6:$C$20000,"Internal Exam",'Inspection History'!$D$6:$D$20000,"Pass")=0,"",_xlfn.MAXIFS('Inspection History'!$A$6:$A$20000,'Inspection History'!$B$6:$B$20000,$A7,'Inspection History'!$C$6:$C$20000,"Internal Exam",'Inspection History'!$D$6:$D$20000,"Pass")) | I7: =IF(OR($C7="",AND($H7="",$P7="")),"",EDATE(IF($H7="",$P7,$H7),12*INDEX(Intervals!$B$14:$B$18,MATCH($C7,Intervals!$A$14:$A$18,0)))) -> 47849 | J7: =IF(_xlfn.MAXIFS('Inspection History'!$A$6:$A$20000,'Inspection History'!$B$6:$B$20000,$A7,'Inspection History'!$C$6:$C$20000,"Hydro Test",'Inspection History'!$D$6:$D$20000,"Pass")=0,"",_xlfn.MAXIFS('Inspection History'!$A$6:$A$20000,'Inspection History'!$B$6:$B$20000,$A7,'Inspection History'!$C$6:$C$20000,"Hydro Test",'Inspection History'!$D$6:$D$20000,"Pass")) | K7: =IF(OR($C7="",AND($J7="",$P7="")),"",EDATE(IF($J7="",$P7,$J7),12*INDEX(Intervals!$C$14:$C$18,MATCH($C7,Intervals!$A$14:$A$18,0)))) -> 47849 | L7: =IF(COUNT($E7,$G7,$I7,$K7)=0,"—",IF(MIN($E7,$G7,$I7,$K7)=$E7,"Monthly inspection",IF(MIN($E7,$G7,$I7,$K7)=$G7,"Annual maintenance",IF(MIN($E7,$G7,$I7,$K7)=$I7,"Internal exam","Hydrostatic test")))) -> Monthly inspection | M7: =IF(COUNT($E7,$G7,$I7,$K7)=0,"",MIN($E7,$G7,$I7,$K7)-TODAY()) -> 30 | N7: =IF($M7="","NOT LOGGED",IF($M7<=0,"OVERDUE",IF($M7<=Intervals!$C$26,"DUE SOON","OK"))) -> OK | P7: 46023 | Q7: =IF($D7="","",IF(SUMPRODUCT(MAX(('Inspection History'!$B$6:$B$20000=$A7)*('Inspection History'!$C$6:$C$20000="Monthly Insp")*('Inspection History'!$D$6:$D$20000="Pass")*('Inspection History'!$A$6:$A$20000=$D7)*ROW('Inspection History'!$A$6:$A$20000)))=0,"",INDEX('Inspection History'!$E:$E,SUMPRODUCT(MAX(('Inspection History'!$B$6:$B$20000=$A7)*('Inspection History'!$C$6:$C$20000="Monthly Insp")*('Inspection History'!$D$6:$D$20000="Pass")*('Inspection History'!$A$6:$A$20000=$D7)*ROW('Inspection History'!$A$6:$A$20000))))&"")) -> J. Godek
A8: FE3 | B8: Break Room | C8: Dry chemical, stored pressure | D8: =IF(_xlfn.MAXIFS('Inspection History'!$A$6:$A$20000,'Inspection History'!$B$6:$B$20000,$A8,'Inspection History'!$C$6:$C$20000,"Monthly Insp",'Inspection History'!$D$6:$D$20000,"Pass")=0,"",_xlfn.MAXIFS('Inspection History'!$A$6:$A$20000,'Inspection History'!$B$6:$B$20000,$A8,'Inspection History'!$C$6:$C$20000,"Monthly Insp",'Inspection History'!$D$6:$D$20000,"Pass")) -> 46321 | E8: =IF($D8="","",$D8+Intervals!$C$5) -> 46351 | F8: =IF(_xlfn.MAXIFS('Inspection History'!$A$6:$A$20000,'Inspection History'!$B$6:$B$20000,$A8,'Inspection History'!$C$6:$C$20000,"Annual Maint",'Inspection History'!$D$6:$D$20000,"Pass")=0,"",_xlfn.MAXIFS('Inspection History'!$A$6:$A$20000,'Inspection History'!$B$6:$B$20000,$A8,'Inspection History'!$C$6:$C$20000,"Annual Maint",'Inspection History'!$D$6:$D$20000,"Pass")) -> 46082 | G8: =IF($F8="","",EDATE($F8,Intervals!$C$6)) -> 46447 | H8: =IF(_xlfn.MAXIFS('Inspection History'!$A$6:$A$20000,'Inspection History'!$B$6:$B$20000,$A8,'Inspection History'!$C$6:$C$20000,"Internal Exam",'Inspection History'!$D$6:$D$20000,"Pass")=0,"",_xlfn.MAXIFS('Inspection History'!$A$6:$A$20000,'Inspection History'!$B$6:$B$20000,$A8,'Inspection History'!$C$6:$C$20000,"Internal Exam",'Inspection History'!$D$6:$D$20000,"Pass")) | I8: =IF(OR($C8="",AND($H8="",$P8="")),"",EDATE(IF($H8="",$P8,$H8),12*INDEX(Intervals!$B$14:$B$18,MATCH($C8,Intervals!$A$14:$A$18,0)))) -> 48214 | J8: =IF(_xlfn.MAXIFS('Inspection History'!$A$6:$A$20000,'Inspection History'!$B$6:$B$20000,$A8,'Inspection History'!$C$6:$C$20000,"Hydro Test",'Inspection History'!$D$6:$D$20000,"Pass")=0,"",_xlfn.MAXIFS('Inspection History'!$A$6:$A$20000,'Inspection History'!$B$6:$B$20000,$A8,'Inspection History'!$C$6:$C$20000,"Hydro Test",'Inspection History'!$D$6:$D$20000,"Pass")) | K8: =IF(OR($C8="",AND($J8="",$P8="")),"",EDATE(IF($J8="",$P8,$J8),12*INDEX(Intervals!$C$14:$C$18,MATCH($C8,Intervals!$A$14:$A$18,0)))) -> 50406 | L8: =IF(COUNT($E8,$G8,$I8,$K8)=0,"—",IF(MIN($E8,$G8,$I8,$K8)=$E8,"Monthly inspection",IF(MIN($E8,$G8,$I8,$K8)=$G8,"Annual maintenance",IF(MIN($E8,$G8,$I8,$K8)=$I8,"Internal exam","Hydrostatic test")))) -> Monthly inspection | M8: =IF(COUNT($E8,$G8,$I8,$K8)=0,"",MIN($E8,$G8,$I8,$K8)-TODAY()) -> 30 | N8: =IF($M8="","NOT LOGGED",IF($M8<=0,"OVERDUE",IF($M8<=Intervals!$C$26,"DUE SOON","OK"))) -> OK | P8: 46023 | Q8: =IF($D8="","",IF(SUMPRODUCT(MAX(('Inspection History'!$B$6:$B$20000=$A8)*('Inspection History'!$C$6:$C$20000="Monthly Insp")*('Inspection History'!$D$6:$D$20000="Pass")*('Inspection History'!$A$6:$A$20000=$D8)*ROW('Inspection History'!$A$6:$A$20000)))=0,"",INDEX('Inspection History'!$E:$E,SUMPRODUCT(MAX(('Inspection History'!$B$6:$B$20000=$A8)*('Inspection History'!$C$6:$C$20000="Monthly Insp")*('Inspection History'!$D$6:$D$20000="Pass")*('Inspection History'!$A$6:$A$20000=$D8)*ROW('Inspection History'!$A$6:$A$20000))))&"")) -> J. Godek
A9: FE4 | B9: Training Room | C9: Carbon dioxide (CO2) | D9: =IF(_xlfn.MAXIFS('Inspection History'!$A$6:$A$20000,'Inspection History'!$B$6:$B$20000,$A9,'Inspection History'!$C$6:$C$20000,"Monthly Insp",'Inspection History'!$D$6:$D$20000,"Pass")=0,"",_xlfn.MAXIFS('Inspection History'!$A$6:$A$20000,'Inspection History'!$B$6:$B$20000,$A9,'Inspection History'!$C$6:$C$20000,"Monthly Insp",'Inspection History'!$D$6:$D$20000,"Pass")) -> 46321 | E9: =IF($D9="","",$D9+Intervals!$C$5) -> 46351 | F9: =IF(_xlfn.MAXIFS('Inspection History'!$A$6:$A$20000,'Inspection History'!$B$6:$B$20000,$A9,'Inspection History'!$C$6:$C$20000,"Annual Maint",'Inspection History'!$D$6:$D$20000,"Pass")=0,"",_xlfn.MAXIFS('Inspection History'!$A$6:$A$20000,'Inspection History'!$B$6:$B$20000,$A9,'Inspection History'!$C$6:$C$20000,"Annual Maint",'Inspection History'!$D$6:$D$20000,"Pass")) -> 46082 | G9: =IF($F9="","",EDATE($F9,Intervals!$C$6)) -> 46447 | H9: =IF(_xlfn.MAXIFS('Inspection History'!$A$6:$A$20000,'Inspection History'!$B$6:$B$20000,$A9,'Inspection History'!$C$6:$C$20000,"Internal Exam",'Inspection History'!$D$6:$D$20000,"Pass")=0,"",_xlfn.MAXIFS('Inspection History'!$A$6:$A$20000,'Inspection History'!$B$6:$B$20000,$A9,'Inspection History'!$C$6:$C$20000,"Internal Exam",'Inspection History'!$D$6:$D$20000,"Pass")) | I9: =IF(OR($C9="",AND($H9="",$P9="")),"",EDATE(IF($H9="",$P9,$H9),12*INDEX(Intervals!$B$14:$B$18,MATCH($C9,Intervals!$A$14:$A$18,0)))) -> 47849 | J9: =IF(_xlfn.MAXIFS('Inspection History'!$A$6:$A$20000,'Inspection History'!$B$6:$B$20000,$A9,'Inspection History'!$C$6:$C$20000,"Hydro Test",'Inspection History'!$D$6:$D$20000,"Pass")=0,"",_xlfn.MAXIFS('Inspection History'!$A$6:$A$20000,'Inspection History'!$B$6:$B$20000,$A9,'Inspection History'!$C$6:$C$20000,"Hydro Test",'Inspection History'!$D$6:$D$20000,"Pass")) | K9: =IF(OR($C9="",AND($J9="",$P9="")),"",EDATE(IF($J9="",$P9,$J9),12*INDEX(Intervals!$C$14:$C$18,MATCH($C9,Intervals!$A$14:$A$18,0)))) -> 47849 | L9: =IF(COUNT($E9,$G9,$I9,$K9)=0,"—",IF(MIN($E9,$G9,$I9,$K9)=$E9,"Monthly inspection",IF(MIN($E9,$G9,$I9,$K9)=$G9,"Annual maintenance",IF(MIN($E9,$G9,$I9,$K9)=$I9,"Internal exam","Hydrostatic test")))) -> Monthly inspection | M9: =IF(COUNT($E9,$G9,$I9,$K9)=0,"",MIN($E9,$G9,$I9,$K9)-TODAY()) -> 30 | N9: =IF($M9="","NOT LOGGED",IF($M9<=0,"OVERDUE",IF($M9<=Intervals!$C$26,"DUE SOON","OK"))) -> OK | P9: 46023 | Q9: =IF($D9="","",IF(SUMPRODUCT(MAX(('Inspection History'!$B$6:$B$20000=$A9)*('Inspection History'!$C$6:$C$20000="Monthly Insp")*('Inspection History'!$D$6:$D$20000="Pass")*('Inspection History'!$A$6:$A$20000=$D9)*ROW('Inspection History'!$A$6:$A$20000)))=0,"",INDEX('Inspection History'!$E:$E,SUMPRODUCT(MAX(('Inspection History'!$B$6:$B$20000=$A9)*('Inspection History'!$C$6:$C$20000="Monthly Insp")*('Inspection History'!$D$6:$D$20000="Pass")*('Inspection History'!$A$6:$A$20000=$D9)*ROW('Inspection History'!$A$6:$A$20000))))&"")) -> J. Godek
A10: FE5 | B10: 190 Ton press bay | C10: Carbon dioxide (CO2) | D10: =IF(_xlfn.MAXIFS('Inspection History'!$A$6:$A$20000,'Inspection History'!$B$6:$B$20000,$A10,'Inspection History'!$C$6:$C$20000,"Monthly Insp",'Inspection History'!$D$6:$D$20000,"Pass")=0,"",_xlfn.MAXIFS('Inspection History'!$A$6:$A$20000,'Inspection History'!$B$6:$B$20000,$A10,'Inspection History'!$C$6:$C$20000,"Monthly Insp",'Inspection History'!$D$6:$D$20000,"Pass")) -> 46321 | E10: =IF($D10="","",$D10+Intervals!$C$5) -> 46351 | F10: =IF(_xlfn.MAXIFS('Inspection History'!$A$6:$A$20000,'Inspection History'!$B$6:$B$20000,$A10,'Inspection History'!$C$6:$C$20000,"Annual Maint",'Inspection History'!$D$6:$D$20000,"Pass")=0,"",_xlfn.MAXIFS('Inspection History'!$A$6:$A$20000,'Inspection History'!$B$6:$B$20000,$A10,'Inspection History'!$C$6:$C$20000,"Annual Maint",'Inspection History'!$D$6:$D$20000,"Pass")) -> 46082 | G10: =IF($F10="","",EDATE($F10,Intervals!$C$6)) -> 46447 | H10: =IF(_xlfn.MAXIFS('Inspection History'!$A$6:$A$20000,'Inspection History'!$B$6:$B$20000,$A10,'Inspection History'!$C$6:$C$20000,"Internal Exam",'Inspection History'!$D$6:$D$20000,"Pass")=0,"",_xlfn.MAXIFS('Inspection History'!$A$6:$A$20000,'Inspection History'!$B$6:$B$20000,$A10,'Inspection History'!$C$6:$C$20000,"Internal Exam",'Inspection History'!$D$6:$D$20000,"Pass")) | I10: =IF(OR($C10="",AND($H10="",$P10="")),"",EDATE(IF($H10="",$P10,$H10),12*INDEX(Intervals!$B$14:$B$18,MATCH($C10,Intervals!$A$14:$A$18,0)))) -> 47849 | J10: =IF(_xlfn.MAXIFS('Inspection History'!$A$6:$A$20000,'Inspection History'!$B$6:$B$20000,$A10,'Inspection History'!$C$6:$C$20000,"Hydro Test",'Inspection History'!$D$6:$D$20000,"Pass")=0,"",_xlfn.MAXIFS('Inspection History'!$A$6:$A$20000,'Inspection History'!$B$6:$B$20000,$A10,'Inspection History'!$C$6:$C$20000,"Hydro Test",'Inspection History'!$D$6:$D$20000,"Pass")) | K10: =IF(OR($C10="",AND($J10="",$P10="")),"",EDATE(IF($J10="",$P10,$J10),12*INDEX(Intervals!$C$14:$C$18,MATCH($C10,Intervals!$A$14:$A$18,0)))) -> 47849 | L10: =IF(COUNT($E10,$G10,$I10,$K10)=0,"—",IF(MIN($E10,$G10,$I10,$K10)=$E10,"Monthly inspection",IF(MIN($E10,$G10,$I10,$K10)=$G10,"Annual maintenance",IF(MIN($E10,$G10,$I10,$K10)=$I10,"Internal exam","Hydrostatic test")))) -> Monthly inspection | M10: =IF(COUNT($E10,$G10,$I10,$K10)=0,"",MIN($E10,$G10,$I10,$K10)-TODAY()) -> 30 | N10: =IF($M10="","NOT LOGGED",IF($M10<=0,"OVERDUE",IF($M10<=Intervals!$C$26,"DUE SOON","OK"))) -> OK | P10: 46023 | Q10: =IF($D10="","",IF(SUMPRODUCT(MAX(('Inspection History'!$B$6:$B$20000=$A10)*('Inspection History'!$C$6:$C$20000="Monthly Insp")*('Inspection History'!$D$6:$D$20000="Pass")*('Inspection History'!$A$6:$A$20000=$D10)*ROW('Inspection History'!$A$6:$A$20000)))=0,"",INDEX('Inspection History'!$E:$E,SUMPRODUCT(MAX(('Inspection History'!$B$6:$B$20000=$A10)*('Inspection History'!$C$6:$C$20000="Monthly Insp")*('Inspection History'!$D$6:$D$20000="Pass")*('Inspection History'!$A$6:$A$20000=$D10)*ROW('Inspection History'!$A$6:$A$20000))))&"")) -> J. Godek
A11: FE6 | B11: Supervisors area | C11: Carbon dioxide (CO2) | D11: =IF(_xlfn.MAXIFS('Inspection History'!$A$6:$A$20000,'Inspection History'!$B$6:$B$20000,$A11,'Inspection History'!$C$6:$C$20000,"Monthly Insp",'Inspection History'!$D$6:$D$20000,"Pass")=0,"",_xlfn.MAXIFS('Inspection History'!$A$6:$A$20000,'Inspection History'!$B$6:$B$20000,$A11,'Inspection History'!$C$6:$C$20000,"Monthly Insp",'Inspection History'!$D$6:$D$20000,"Pass")) -> 46321 | E11: =IF($D11="","",$D11+Intervals!$C$5) -> 46351 | F11: =IF(_xlfn.MAXIFS('Inspection History'!$A$6:$A$20000,'Inspection History'!$B$6:$B$20000,$A11,'Inspection History'!$C$6:$C$20000,"Annual Maint",'Inspection History'!$D$6:$D$20000,"Pass")=0,"",_xlfn.MAXIFS('Inspection History'!$A$6:$A$20000,'Inspection History'!$B$6:$B$20000,$A11,'Inspection History'!$C$6:$C$20000,"Annual Maint",'Inspection History'!$D$6:$D$20000,"Pass")) -> 46082 | G11: =IF($F11="","",EDATE($F11,Intervals!$C$6)) -> 46447 | H11: =IF(_xlfn.MAXIFS('Inspection History'!$A$6:$A$20000,'Inspection History'!$B$6:$B$20000,$A11,'Inspection History'!$C$6:$C$20000,"Internal Exam",'Inspection History'!$D$6:$D$20000,"Pass")=0,"",_xlfn.MAXIFS('Inspection History'!$A$6:$A$20000,'Inspection History'!$B$6:$B$20000,$A11,'Inspection History'!$C$6:$C$20000,"Internal Exam",'Inspection History'!$D$6:$D$20000,"Pass")) | I11: =IF(OR($C11="",AND($H11="",$P11="")),"",EDATE(IF($H11="",$P11,$H11),12*INDEX(Intervals!$B$14:$B$18,MATCH($C11,Intervals!$A$14:$A$18,0)))) -> 47849 | J11: =IF(_xlfn.MAXIFS('Inspection History'!$A$6:$A$20000,'Inspection History'!$B$6:$B$20000,$A11,'Inspection History'!$C$6:$C$20000,"Hydro Test",'Inspection History'!$D$6:$D$20000,"Pass")=0,"",_xlfn.MAXIFS('Inspection History'!$A$6:$A$20000,'Inspection History'!$B$6:$B$20000,$A11,'Inspection History'!$C$6:$C$20000,"Hydro Test",'Inspection History'!$D$6:$D$20000,"Pass")) | K11: =IF(OR($C11="",AND($J11="",$P11="")),"",EDATE(IF($J11="",$P11,$J11),12*INDEX(Intervals!$C$14:$C$18,MATCH($C11,Intervals!$A$14:$A$18,0)))) -> 47849 | L11: =IF(COUNT($E11,$G11,$I11,$K11)=0,"—",IF(MIN($E11,$G11,$I11,$K11)=$E11,"Monthly inspection",IF(MIN($E11,$G11,$I11,$K11)=$G11,"Annual maintenance",IF(MIN($E11,$G11,$I11,$K11)=$I11,"Internal exam","Hydrostatic test")))) -> Monthly inspection | M11: =IF(COUNT($E11,$G11,$I11,$K11)=0,"",MIN($E11,$G11,$I11,$K11)-TODAY()) -> 30 | N11: =IF($M11="","NOT LOGGED",IF($M11<=0,"OVERDUE",IF($M11<=Intervals!$C$26,"DUE SOON","OK"))) -> OK | P11: 46023 | Q11: =IF($D11="","",IF(SUMPRODUCT(MAX(('Inspection History'!$B$6:$B$20000=$A11)*('Inspection History'!$C$6:$C$20000="Monthly Insp")*('Inspection History'!$D$6:$D$20000="Pass")*('Inspection History'!$A$6:$A$20000=$D11)*ROW('Inspection History'!$A$6:$A$20000)))=0,"",INDEX('Inspection History'!$E:$E,SUMPRODUCT(MAX(('Inspection History'!$B$6:$B$20000=$A11)*('Inspection History'!$C$6:$C$20000="Monthly Insp")*('Inspection History'!$D$6:$D$20000="Pass")*('Inspection History'!$A$6:$A$20000=$D11)*ROW('Inspection History'!$A$6:$A$20000))))&"")) -> J. Godek
A12: FE7 | B12: Office Area (near Warehouse aisle) | C12: Carbon dioxide (CO2) | D12: =IF(_xlfn.MAXIFS('Inspection History'!$A$6:$A$20000,'Inspection History'!$B$6:$B$20000,$A12,'Inspection History'!$C$6:$C$20000,"Monthly Insp",'Inspection History'!$D$6:$D$20000,"Pass")=0,"",_xlfn.MAXIFS('Inspection History'!$A$6:$A$20000,'Inspection History'!$B$6:$B$20000,$A12,'Inspection History'!$C$6:$C$20000,"Monthly Insp",'Inspection History'!$D$6:$D$20000,"Pass")) -> 46321 | E12: =IF($D12="","",$D12+Intervals!$C$5) -> 46351 | F12: =IF(_xlfn.MAXIFS('Inspection History'!$A$6:$A$20000,'Inspection History'!$B$6:$B$20000,$A12,'Inspection History'!$C$6:$C$20000,"Annual Maint",'Inspection History'!$D$6:$D$20000,"Pass")=0,"",_xlfn.MAXIFS('Inspection History'!$A$6:$A$20000,'Inspection History'!$B$6:$B$20000,$A12,'Inspection History'!$C$6:$C$20000,"Annual Maint",'Inspection History'!$D$6:$D$20000,"Pass")) -> 46082 | G12: =IF($F12="","",EDATE($F12,Intervals!$C$6)) -> 46447 | H12: =IF(_xlfn.MAXIFS('Inspection History'!$A$6:$A$20000,'Inspection History'!$B$6:$B$20000,$A12,'Inspection History'!$C$6:$C$20000,"Internal Exam",'Inspection History'!$D$6:$D$20000,"Pass")=0,"",_xlfn.MAXIFS('Inspection History'!$A$6:$A$20000,'Inspection History'!$B$6:$B$20000,$A12,'Inspection History'!$C$6:$C$20000,"Internal Exam",'Inspection History'!$D$6:$D$20000,"Pass")) | I12: =IF(OR($C12="",AND($H12="",$P12="")),"",EDATE(IF($H12="",$P12,$H12),12*INDEX(Intervals!$B$14:$B$18,MATCH($C12,Intervals!$A$14:$A$18,0)))) -> 47849 | J12: =IF(_xlfn.MAXIFS('Inspection History'!$A$6:$A$20000,'Inspection History'!$B$6:$B$20000,$A12,'Inspection History'!$C$6:$C$20000,"Hydro Test",'Inspection History'!$D$6:$D$20000,"Pass")=0,"",_xlfn.MAXIFS('Inspection History'!$A$6:$A$20000,'Inspection History'!$B$6:$B$20000,$A12,'Inspection History'!$C$6:$C$20000,"Hydro Test",'Inspection History'!$D$6:$D$20000,"Pass")) | K12: =IF(OR($C12="",AND($J12="",$P12="")),"",EDATE(IF($J12="",$P12,$J12),12*INDEX(Intervals!$C$14:$C$18,MATCH($C12,Intervals!$A$14:$A$18,0)))) -> 47849 | L12: =IF(COUNT($E12,$G12,$I12,$K12)=0,"—",IF(MIN($E12,$G12,$I12,$K12)=$E12,"Monthly inspection",IF(MIN($E12,$G12,$I12,$K12)=$G12,"Annual maintenance",IF(MIN($E12,$G12,$I12,$K12)=$I12,"Internal exam","Hydrostatic test")))) -> Monthly inspection | M12: =IF(COUNT($E12,$G12,$I12,$K12)=0,"",MIN($E12,$G12,$I12,$K12)-TODAY()) -> 30 | N12: =IF($M12="","NOT LOGGED",IF($M12<=0,"OVERDUE",IF($M12<=Intervals!$C$26,"DUE SOON","OK"))) -> OK | P12: 46023 | Q12: =IF($D12="","",IF(SUMPRODUCT(MAX(('Inspection History'!$B$6:$B$20000=$A12)*('Inspection History'!$C$6:$C$20000="Monthly Insp")*('Inspection History'!$D$6:$D$20000="Pass")*('Inspection History'!$A$6:$A$20000=$D12)*ROW('Inspection History'!$A$6:$A$20000)))=0,"",INDEX('Inspection History'!$E:$E,SUMPRODUCT(MAX(('Inspection History'!$B$6:$B$20000=$A12)*('Inspection History'!$C$6:$C$20000="Monthly Insp")*('Inspection History'!$D$6:$D$20000="Pass")*('Inspection History'!$A$6:$A$20000=$D12)*ROW('Inspection History'!$A$6:$A$20000))))&"")) -> J. Godek
A13: FE8 | B13: Warehouse Area | C13: Dry chemical, stored pressure | D13: =IF(_xlfn.MAXIFS('Inspection History'!$A$6:$A$20000,'Inspection History'!$B$6:$B$20000,$A13,'Inspection History'!$C$6:$C$20000,"Monthly Insp",'Inspection History'!$D$6:$D$20000,"Pass")=0,"",_xlfn.MAXIFS('Inspection History'!$A$6:$A$20000,'Inspection History'!$B$6:$B$20000,$A13,'Inspection History'!$C$6:$C$20000,"Monthly Insp",'Inspection History'!$D$6:$D$20000,"Pass")) -> 46321 | E13: =IF($D13="","",$D13+Intervals!$C$5) -> 46351 | F13: =IF(_xlfn.MAXIFS('Inspection History'!$A$6:$A$20000,'Inspection History'!$B$6:$B$20000,$A13,'Inspection History'!$C$6:$C$20000,"Annual Maint",'Inspection History'!$D$6:$D$20000,"Pass")=0,"",_xlfn.MAXIFS('Inspection History'!$A$6:$A$20000,'Inspection History'!$B$6:$B$20000,$A13,'Inspection History'!$C$6:$C$20000,"Annual Maint",'Inspection History'!$D$6:$D$20000,"Pass")) -> 46082 | G13: =IF($F13="","",EDATE($F13,Intervals!$C$6)) -> 46447 | H13: =IF(_xlfn.MAXIFS('Inspection History'!$A$6:$A$20000,'Inspection History'!$B$6:$B$20000,$A13,'Inspection History'!$C$6:$C$20000,"Internal Exam",'Inspection History'!$D$6:$D$20000,"Pass")=0,"",_xlfn.MAXIFS('Inspection History'!$A$6:$A$20000,'Inspection History'!$B$6:$B$20000,$A13,'Inspection History'!$C$6:$C$20000,"Internal Exam",'Inspection History'!$D$6:$D$20000,"Pass")) | I13: =IF(OR($C13="",AND($H13="",$P13="")),"",EDATE(IF($H13="",$P13,$H13),12*INDEX(Intervals!$B$14:$B$18,MATCH($C13,Intervals!$A$14:$A$18,0)))) -> 48214 | J13: =IF(_xlfn.MAXIFS('Inspection History'!$A$6:$A$20000,'Inspection History'!$B$6:$B$20000,$A13,'Inspection History'!$C$6:$C$20000,"Hydro Test",'Inspection History'!$D$6:$D$20000,"Pass")=0,"",_xlfn.MAXIFS('Inspection History'!$A$6:$A$20000,'Inspection History'!$B$6:$B$20000,$A13,'Inspection History'!$C$6:$C$20000,"Hydro Test",'Inspection History'!$D$6:$D$20000,"Pass")) | K13: =IF(OR($C13="",AND($J13="",$P13="")),"",EDATE(IF($J13="",$P13,$J13),12*INDEX(Intervals!$C$14:$C$18,MATCH($C13,Intervals!$A$14:$A$18,0)))) -> 50406 | L13: =IF(COUNT($E13,$G13,$I13,$K13)=0,"—",IF(MIN($E13,$G13,$I13,$K13)=$E13,"Monthly inspection",IF(MIN($E13,$G13,$I13,$K13)=$G13,"Annual maintenance",IF(MIN($E13,$G13,$I13,$K13)=$I13,"Internal exam","Hydrostatic test")))) -> Monthly inspection | M13: =IF(COUNT($E13,$G13,$I13,$K13)=0,"",MIN($E13,$G13,$I13,$K13)-TODAY()) -> 30 | N13: =IF($M13="","NOT LOGGED",IF($M13<=0,"OVERDUE",IF($M13<=Intervals!$C$26,"DUE SOON","OK"))) -> OK | P13: 46023 | Q13: =IF($D13="","",IF(SUMPRODUCT(MAX(('Inspection History'!$B$6:$B$20000=$A13)*('Inspection History'!$C$6:$C$20000="Monthly Insp")*('Inspection History'!$D$6:$D$20000="Pass")*('Inspection History'!$A$6:$A$20000=$D13)*ROW('Inspection History'!$A$6:$A$20000)))=0,"",INDEX('Inspection History'!$E:$E,SUMPRODUCT(MAX(('Inspection History'!$B$6:$B$20000=$A13)*('Inspection History'!$C$6:$C$20000="Monthly Insp")*('Inspection History'!$D$6:$D$20000="Pass")*('Inspection History'!$A$6:$A$20000=$D13)*ROW('Inspection History'!$A$6:$A$20000))))&"")) -> J. Godek
A14: FE9 | B14: 1400 Ton press bay | C14: Dry chemical, stored pressure | D14: =IF(_xlfn.MAXIFS('Inspection History'!$A$6:$A$20000,'Inspection History'!$B$6:$B$20000,$A14,'Inspection History'!$C$6:$C$20000,"Monthly Insp",'Inspection History'!$D$6:$D$20000,"Pass")=0,"",_xlfn.MAXIFS('Inspection History'!$A$6:$A$20000,'Inspection History'!$B$6:$B$20000,$A14,'Inspection History'!$C$6:$C$20000,"Monthly Insp",'Inspection History'!$D$6:$D$20000,"Pass")) -> 46321 | E14: =IF($D14="","",$D14+Intervals!$C$5) -> 46351 | F14: =IF(_xlfn.MAXIFS('Inspection History'!$A$6:$A$20000,'Inspection History'!$B$6:$B$20000,$A14,'Inspection History'!$C$6:$C$20000,"Annual Maint",'Inspection History'!$D$6:$D$20000,"Pass")=0,"",_xlfn.MAXIFS('Inspection History'!$A$6:$A$20000,'Inspection History'!$B$6:$B$20000,$A14,'Inspection History'!$C$6:$C$20000,"Annual Maint",'Inspection History'!$D$6:$D$20000,"Pass")) -> 46082 | G14: =IF($F14="","",EDATE($F14,Intervals!$C$6)) -> 46447 | H14: =IF(_xlfn.MAXIFS('Inspection History'!$A$6:$A$20000,'Inspection History'!$B$6:$B$20000,$A14,'Inspection History'!$C$6:$C$20000,"Internal Exam",'Inspection History'!$D$6:$D$20000,"Pass")=0,"",_xlfn.MAXIFS('Inspection History'!$A$6:$A$20000,'Inspection History'!$B$6:$B$20000,$A14,'Inspection History'!$C$6:$C$20000,"Internal Exam",'Inspection History'!$D$6:$D$20000,"Pass")) | I14: =IF(OR($C14="",AND($H14="",$P14="")),"",EDATE(IF($H14="",$P14,$H14),12*INDEX(Intervals!$B$14:$B$18,MATCH($C14,Intervals!$A$14:$A$18,0)))) -> 48214 | J14: =IF(_xlfn.MAXIFS('Inspection History'!$A$6:$A$20000,'Inspection History'!$B$6:$B$20000,$A14,'Inspection History'!$C$6:$C$20000,"Hydro Test",'Inspection History'!$D$6:$D$20000,"Pass")=0,"",_xlfn.MAXIFS('Inspection History'!$A$6:$A$20000,'Inspection History'!$B$6:$B$20000,$A14,'Inspection History'!$C$6:$C$20000,"Hydro Test",'Inspection History'!$D$6:$D$20000,"Pass")) | K14: =IF(OR($C14="",AND($J14="",$P14="")),"",EDATE(IF($J14="",$P14,$J14),12*INDEX(Intervals!$C$14:$C$18,MATCH($C14,Intervals!$A$14:$A$18,0)))) -> 50406 | L14: =IF(COUNT($E14,$G14,$I14,$K14)=0,"—",IF(MIN($E14,$G14,$I14,$K14)=$E14,"Monthly inspection",IF(MIN($E14,$G14,$I14,$K14)=$G14,"Annual maintenance",IF(MIN($E14,$G14,$I14,$K14)=$I14,"Internal exam","Hydrostatic test")))) -> Monthly inspection | M14: =IF(COUNT($E14,$G14,$I14,$K14)=0,"",MIN($E14,$G14,$I14,$K14)-TODAY()) -> 30 | N14: =IF($M14="","NOT LOGGED",IF($M14<=0,"OVERDUE",IF($M14<=Intervals!$C$26,"DUE SOON","OK"))) -> OK | P14: 46023 | Q14: =IF($D14="","",IF(SUMPRODUCT(MAX(('Inspection History'!$B$6:$B$20000=$A14)*('Inspection History'!$C$6:$C$20000="Monthly Insp")*('Inspection History'!$D$6:$D$20000="Pass")*('Inspection History'!$A$6:$A$20000=$D14)*ROW('Inspection History'!$A$6:$A$20000)))=0,"",INDEX('Inspection History'!$E:$E,SUMPRODUCT(MAX(('Inspection History'!$B$6:$B$20000=$A14)*('Inspection History'!$C$6:$C$20000="Monthly Insp")*('Inspection History'!$D$6:$D$20000="Pass")*('Inspection History'!$A$6:$A$20000=$D14)*ROW('Inspection History'!$A$6:$A$20000))))&"")) -> J. Godek
A15: FE10 | B15: 310 Ton press bay | C15: Dry chemical, stored pressure | D15: =IF(_xlfn.MAXIFS('Inspection History'!$A$6:$A$20000,'Inspection History'!$B$6:$B$20000,$A15,'Inspection History'!$C$6:$C$20000,"Monthly Insp",'Inspection History'!$D$6:$D$20000,"Pass")=0,"",_xlfn.MAXIFS('Inspection History'!$A$6:$A$20000,'Inspection History'!$B$6:$B$20000,$A15,'Inspection History'!$C$6:$C$20000,"Monthly Insp",'Inspection History'!$D$6:$D$20000,"Pass")) -> 46321 | E15: =IF($D15="","",$D15+Intervals!$C$5) -> 46351 | F15: =IF(_xlfn.MAXIFS('Inspection History'!$A$6:$A$20000,'Inspection History'!$B$6:$B$20000,$A15,'Inspection History'!$C$6:$C$20000,"Annual Maint",'Inspection History'!$D$6:$D$20000,"Pass")=0,"",_xlfn.MAXIFS('Inspection History'!$A$6:$A$20000,'Inspection History'!$B$6:$B$20000,$A15,'Inspection History'!$C$6:$C$20000,"Annual Maint",'Inspection History'!$D$6:$D$20000,"Pass")) -> 46082 | G15: =IF($F15="","",EDATE($F15,Intervals!$C$6)) -> 46447 | H15: =IF(_xlfn.MAXIFS('Inspection History'!$A$6:$A$20000,'Inspection History'!$B$6:$B$20000,$A15,'Inspection History'!$C$6:$C$20000,"Internal Exam",'Inspection History'!$D$6:$D$20000,"Pass")=0,"",_xlfn.MAXIFS('Inspection History'!$A$6:$A$20000,'Inspection History'!$B$6:$B$20000,$A15,'Inspection History'!$C$6:$C$20000,"Internal Exam",'Inspection History'!$D$6:$D$20000,"Pass")) | I15: =IF(OR($C15="",AND($H15="",$P15="")),"",EDATE(IF($H15="",$P15,$H15),12*INDEX(Intervals!$B$14:$B$18,MATCH($C15,Intervals!$A$14:$A$18,0)))) -> 48214 | J15: =IF(_xlfn.MAXIFS('Inspection History'!$A$6:$A$20000,'Inspection History'!$B$6:$B$20000,$A15,'Inspection History'!$C$6:$C$20000,"Hydro Test",'Inspection History'!$D$6:$D$20000,"Pass")=0,"",_xlfn.MAXIFS('Inspection History'!$A$6:$A$20000,'Inspection History'!$B$6:$B$20000,$A15,'Inspection History'!$C$6:$C$20000,"Hydro Test",'Inspection History'!$D$6:$D$20000,"Pass")) | K15: =IF(OR($C15="",AND($J15="",$P15="")),"",EDATE(IF($J15="",$P15,$J15),12*INDEX(Intervals!$C$14:$C$18,MATCH($C15,Intervals!$A$14:$A$18,0)))) -> 50406 | L15: =IF(COUNT($E15,$G15,$I15,$K15)=0,"—",IF(MIN($E15,$G15,$I15,$K15)=$E15,"Monthly inspection",IF(MIN($E15,$G15,$I15,$K15)=$G15,"Annual maintenance",IF(MIN($E15,$G15,$I15,$K15)=$I15,"Internal exam","Hydrostatic test")))) -> Monthly inspection | M15: =IF(COUNT($E15,$G15,$I15,$K15)=0,"",MIN($E15,$G15,$I15,$K15)-TODAY()) -> 30 | N15: =IF($M15="","NOT LOGGED",IF($M15<=0,"OVERDUE",IF($M15<=Intervals!$C$26,"DUE SOON","OK"))) -> OK | P15: 46023 | Q15: =IF($D15="","",IF(SUMPRODUCT(MAX(('Inspection History'!$B$6:$B$20000=$A15)*('Inspection History'!$C$6:$C$20000="Monthly Insp")*('Inspection History'!$D$6:$D$20000="Pass")*('Inspection History'!$A$6:$A$20000=$D15)*ROW('Inspection History'!$A$6:$A$20000)))=0,"",INDEX('Inspection History'!$E:$E,SUMPRODUCT(MAX(('Inspection History'!$B$6:$B$20000=$A15)*('Inspection History'!$C$6:$C$20000="Monthly Insp")*('Inspection History'!$D$6:$D$20000="Pass")*('Inspection History'!$A$6:$A$20000=$D15)*ROW('Inspection History'!$A$6:$A$20000))))&"")) -> J. Godek
A16: FE11 | B16: Near 310 Ton bay (south aisle) | C16: Dry chemical, stored pressure | D16: =IF(_xlfn.MAXIFS('Inspection History'!$A$6:$A$20000,'Inspection History'!$B$6:$B$20000,$A16,'Inspection History'!$C$6:$C$20000,"Monthly Insp",'Inspection History'!$D$6:$D$20000,"Pass")=0,"",_xlfn.MAXIFS('Inspection History'!$A$6:$A$20000,'Inspection History'!$B$6:$B$20000,$A16,'Inspection History'!$C$6:$C$20000,"Monthly Insp",'Inspection History'!$D$6:$D$20000,"Pass")) -> 46321 | E16: =IF($D16="","",$D16+Intervals!$C$5) -> 46351 | F16: =IF(_xlfn.MAXIFS('Inspection History'!$A$6:$A$20000,'Inspection History'!$B$6:$B$20000,$A16,'Inspection History'!$C$6:$C$20000,"Annual Maint",'Inspection History'!$D$6:$D$20000,"Pass")=0,"",_xlfn.MAXIFS('Inspection History'!$A$6:$A$20000,'Inspection History'!$B$6:$B$20000,$A16,'Inspection History'!$C$6:$C$20000,"Annual Maint",'Inspection History'!$D$6:$D$20000,"Pass")) -> 46082 | G16: =IF($F16="","",EDATE($F16,Intervals!$C$6)) -> 46447 | H16: =IF(_xlfn.MAXIFS('Inspection History'!$A$6:$A$20000,'Inspection History'!$B$6:$B$20000,$A16,'Inspection History'!$C$6:$C$20000,"Internal Exam",'Inspection History'!$D$6:$D$20000,"Pass")=0,"",_xlfn.MAXIFS('Inspection History'!$A$6:$A$20000,'Inspection History'!$B$6:$B$20000,$A16,'Inspection History'!$C$6:$C$20000,"Internal Exam",'Inspection History'!$D$6:$D$20000,"Pass")) | I16: =IF(OR($C16="",AND($H16="",$P16="")),"",EDATE(IF($H16="",$P16,$H16),12*INDEX(Intervals!$B$14:$B$18,MATCH($C16,Intervals!$A$14:$A$18,0)))) -> 48214 | J16: =IF(_xlfn.MAXIFS('Inspection History'!$A$6:$A$20000,'Inspection History'!$B$6:$B$20000,$A16,'Inspection History'!$C$6:$C$20000,"Hydro Test",'Inspection History'!$D$6:$D$20000,"Pass")=0,"",_xlfn.MAXIFS('Inspection History'!$A$6:$A$20000,'Inspection History'!$B$6:$B$20000,$A16,'Inspection History'!$C$6:$C$20000,"Hydro Test",'Inspection History'!$D$6:$D$20000,"Pass")) | K16: =IF(OR($C16="",AND($J16="",$P16="")),"",EDATE(IF($J16="",$P16,$J16),12*INDEX(Intervals!$C$14:$C$18,MATCH($C16,Intervals!$A$14:$A$18,0)))) -> 50406 | L16: =IF(COUNT($E16,$G16,$I16,$K16)=0,"—",IF(MIN($E16,$G16,$I16,$K16)=$E16,"Monthly inspection",IF(MIN($E16,$G16,$I16,$K16)=$G16,"Annual maintenance",IF(MIN($E16,$G16,$I16,$K16)=$I16,"Internal exam","Hydrostatic test")))) -> Monthly inspection | M16: =IF(COUNT($E16,$G16,$I16,$K16)=0,"",MIN($E16,$G16,$I16,$K16)-TODAY()) -> 30 | N16: =IF($M16="","NOT LOGGED",IF($M16<=0,"OVERDUE",IF($M16<=Intervals!$C$26,"DUE SOON","OK"))) -> OK | P16: 46023 | Q16: =IF($D16="","",IF(SUMPRODUCT(MAX(('Inspection History'!$B$6:$B$20000=$A16)*('Inspection History'!$C$6:$C$20000="Monthly Insp")*('Inspection History'!$D$6:$D$20000="Pass")*('Inspection History'!$A$6:$A$20000=$D16)*ROW('Inspection History'!$A$6:$A$20000)))=0,"",INDEX('Inspection History'!$E:$E,SUMPRODUCT(MAX(('Inspection History'!$B$6:$B$20000=$A16)*('Inspection History'!$C$6:$C$20000="Monthly Insp")*('Inspection History'!$D$6:$D$20000="Pass")*('Inspection History'!$A$6:$A$20000=$D16)*ROW('Inspection History'!$A$6:$A$20000))))&"")) -> J. Godek
A17: FE12 | B17: Warehouse Area (east) | C17: Dry chemical, stored pressure | D17: =IF(_xlfn.MAXIFS('Inspection History'!$A$6:$A$20000,'Inspection History'!$B$6:$B$20000,$A17,'Inspection History'!$C$6:$C$20000,"Monthly Insp",'Inspection History'!$D$6:$D$20000,"Pass")=0,"",_xlfn.MAXIFS('Inspection History'!$A$6:$A$20000,'Inspection History'!$B$6:$B$20000,$A17,'Inspection History'!$C$6:$C$20000,"Monthly Insp",'Inspection History'!$D$6:$D$20000,"Pass")) -> 46321 | E17: =IF($D17="","",$D17+Intervals!$C$5) -> 46351 | F17: =IF(_xlfn.MAXIFS('Inspection History'!$A$6:$A$20000,'Inspection History'!$B$6:$B$20000,$A17,'Inspection History'!$C$6:$C$20000,"Annual Maint",'Inspection History'!$D$6:$D$20000,"Pass")=0,"",_xlfn.MAXIFS('Inspection History'!$A$6:$A$20000,'Inspection History'!$B$6:$B$20000,$A17,'Inspection History'!$C$6:$C$20000,"Annual Maint",'Inspection History'!$D$6:$D$20000,"Pass")) -> 46082 | G17: =IF($F17="","",EDATE($F17,Intervals!$C$6)) -> 46447 | H17: =IF(_xlfn.MAXIFS('Inspection History'!$A$6:$A$20000,'Inspection History'!$B$6:$B$20000,$A17,'Inspection History'!$C$6:$C$20000,"Internal Exam",'Inspection History'!$D$6:$D$20000,"Pass")=0,"",_xlfn.MAXIFS('Inspection History'!$A$6:$A$20000,'Inspection History'!$B$6:$B$20000,$A17,'Inspection History'!$C$6:$C$20000,"Internal Exam",'Inspection History'!$D$6:$D$20000,"Pass")) | I17: =IF(OR($C17="",AND($H17="",$P17="")),"",EDATE(IF($H17="",$P17,$H17),12*INDEX(Intervals!$B$14:$B$18,MATCH($C17,Intervals!$A$14:$A$18,0)))) -> 48214 | J17: =IF(_xlfn.MAXIFS('Inspection History'!$A$6:$A$20000,'Inspection History'!$B$6:$B$20000,$A17,'Inspection History'!$C$6:$C$20000,"Hydro Test",'Inspection History'!$D$6:$D$20000,"Pass")=0,"",_xlfn.MAXIFS('Inspection History'!$A$6:$A$20000,'Inspection History'!$B$6:$B$20000,$A17,'Inspection History'!$C$6:$C$20000,"Hydro Test",'Inspection History'!$D$6:$D$20000,"Pass")) | K17: =IF(OR($C17="",AND($J17="",$P17="")),"",EDATE(IF($J17="",$P17,$J17),12*INDEX(Intervals!$C$14:$C$18,MATCH($C17,Intervals!$A$14:$A$18,0)))) -> 50406 | L17: =IF(COUNT($E17,$G17,$I17,$K17)=0,"—",IF(MIN($E17,$G17,$I17,$K17)=$E17,"Monthly inspection",IF(MIN($E17,$G17,$I17,$K17)=$G17,"Annual maintenance",IF(MIN($E17,$G17,$I17,$K17)=$I17,"Internal exam","Hydrostatic test")))) -> Monthly inspection | M17: =IF(COUNT($E17,$G17,$I17,$K17)=0,"",MIN($E17,$G17,$I17,$K17)-TODAY()) -> 30 | N17: =IF($M17="","NOT LOGGED",IF($M17<=0,"OVERDUE",IF($M17<=Intervals!$C$26,"DUE SOON","OK"))) -> OK | P17: 46023 | Q17: =IF($D17="","",IF(SUMPRODUCT(MAX(('Inspection History'!$B$6:$B$20000=$A17)*('Inspection History'!$C$6:$C$20000="Monthly Insp")*('Inspection History'!$D$6:$D$20000="Pass")*('Inspection History'!$A$6:$A$20000=$D17)*ROW('Inspection History'!$A$6:$A$20000)))=0,"",INDEX('Inspection History'!$E:$E,SUMPRODUCT(MAX(('Inspection History'!$B$6:$B$20000=$A17)*('Inspection History'!$C$6:$C$20000="Monthly Insp")*('Inspection History'!$D$6:$D$20000="Pass")*('Inspection History'!$A$6:$A$20000=$D17)*ROW('Inspection History'!$A$6:$A$20000))))&"")) -> J. Godek
... A26: FE21 | B26: Office stairwell (by the conference room) — NEW 08/10/2026 | C26: Dry chemical, stored pressure | D26: =IF(_xlfn.MAXIFS('Inspection History'!$A$6:$A$20000,'Inspection History'!$B$6:$B$20000,$A26,'Inspection History'!$C$6:$C$20000,"Monthly Insp",'Inspection History'!$D$6:$D$20000,"Pass")=0,"",_xlfn.MAXIFS('Inspection History'!$A$6:$A$20000,'Inspection History'!$B$6:$B$20000,$A26,'Inspection History'!$C$6:$C$20000,"Monthly Insp",'Inspection History'!$D$6:$D$20000,"Pass")) -> 46321 | E26: =IF($D26="","",$D26+Intervals!$C$5) -> 46351 | F26: =IF(_xlfn.MAXIFS('Inspection History'!$A$6:$A$20000,'Inspection History'!$B$6:$B$20000,$A26,'Inspection History'!$C$6:$C$20000,"Annual Maint",'Inspection History'!$D$6:$D$20000,"Pass")=0,"",_xlfn.MAXIFS('Inspection History'!$A$6:$A$20000,'Inspection History'!$B$6:$B$20000,$A26,'Inspection History'!$C$6:$C$20000,"Annual Maint",'Inspection History'!$D$6:$D$20000,"Pass")) -> 46082 | G26: =IF($F26="","",EDATE($F26,Intervals!$C$6)) -> 46447 | H26: =IF(_xlfn.MAXIFS('Inspection History'!$A$6:$A$20000,'Inspection History'!$B$6:$B$20000,$A26,'Inspection History'!$C$6:$C$20000,"Internal Exam",'Inspection History'!$D$6:$D$20000,"Pass")=0,"",_xlfn.MAXIFS('Inspection History'!$A$6:$A$20000,'Inspection History'!$B$6:$B$20000,$A26,'Inspection History'!$C$6:$C$20000,"Internal Exam",'Inspection History'!$D$6:$D$20000,"Pass")) | I26: =IF(OR($C26="",AND($H26="",$P26="")),"",EDATE(IF($H26="",$P26,$H26),12*INDEX(Intervals!$B$14:$B$18,MATCH($C26,Intervals!$A$14:$A$18,0)))) -> 48214 | J26: =IF(_xlfn.MAXIFS('Inspection History'!$A$6:$A$20000,'Inspection History'!$B$6:$B$20000,$A26,'Inspection History'!$C$6:$C$20000,"Hydro Test",'Inspection History'!$D$6:$D$20000,"Pass")=0,"",_xlfn.MAXIFS('Inspection History'!$A$6:$A$20000,'Inspection History'!$B$6:$B$20000,$A26,'Inspection History'!$C$6:$C$20000,"Hydro Test",'Inspection History'!$D$6:$D$20000,"Pass")) | K26: =IF(OR($C26="",AND($J26="",$P26="")),"",EDATE(IF($J26="",$P26,$J26),12*INDEX(Intervals!$C$14:$C$18,MATCH($C26,Intervals!$A$14:$A$18,0)))) -> 50406 | L26: =IF(COUNT($E26,$G26,$I26,$K26)=0,"—",IF(MIN($E26,$G26,$I26,$K26)=$E26,"Monthly inspection",IF(MIN($E26,$G26,$I26,$K26)=$G26,"Annual maintenance",IF(MIN($E26,$G26,$I26,$K26)=$I26,"Internal exam","Hydrostatic test")))) -> Monthly inspection | M26: =IF(COUNT($E26,$G26,$I26,$K26)=0,"",MIN($E26,$G26,$I26,$K26)-TODAY()) -> 30 | N26: =IF($M26="","NOT LOGGED",IF($M26<=0,"OVERDUE",IF($M26<=Intervals!$C$26,"DUE SOON","OK"))) -> OK | P26: 46023 | Q26: =IF($D26="","",IF(SUMPRODUCT(MAX(('Inspection History'!$B$6:$B$20000=$A26)*('Inspection History'!$C$6:$C$20000="Monthly Insp")*('Inspection History'!$D$6:$D$20000="Pass")*('Inspection History'!$A$6:$A$20000=$D26)*ROW('Inspection History'!$A$6:$A$20000)))=0,"",INDEX('Inspection History'!$E:$E,SUMPRODUCT(MAX(('Inspection History'!$B$6:$B$20000=$A26)*('Inspection History'!$C$6:$C$20000="Monthly Insp")*('Inspection History'!$D$6:$D$20000="Pass")*('Inspection History'!$A$6:$A$20000=$D26)*ROW('Inspection History'!$A$6:$A$20000))))&"")) -> J. Godek
A28: Dates in mm/dd/yyyy (example: the 07/23/2026 values above). A blank Last date means that check is not tracked and shows NOT LOGGED.
A29: Source: 07/23/2026 baseline sweep supplied by John Godek, Atomic Industries. FE21 added 08/10/2026 from the marked-up plant layout and has no check history yet. Intervals per NFPA 10 — see the Intervals tab.

Sheet EL Log
A1: Emergency Light PM Log — Atomic Industries, 50479 Birch Drive, Shelby Township, MI
A2: Dates come from the Inspection History tab: add a row there, or use Walk mode in the dashboard. Edit only the yellow cells. NFPA 101 7.9.3 requires two separate tests per fixture — a 30-day test held at least 30 seconds, and an annual test held the full 90 minutes on battery.
A3: RENUMBERED 08/10/2026 per the marked-up plant layout: EL1-EL23, of which 7 are newly added fixtures (EL4, EL6, EL8, EL10, EL12, EL22, EL23). The "Was" column maps each row back to its previous ID - relabel the physical fixtures to match. The 7 new fixtures have no check history and read NOT LOGGED until one is recorded.
A5: EL # | B5: Was | C5: Near Location | D5: Last Monthly Test | E5: Next Monthly Test | F5: Last Annual Test | G5: Next Annual Test | H5: Next Action | I5: Days Remaining | J5: Status | K5: Notes | L5: Last Inspected By
A6: EL1 | B6: EL1 | C6: Office Area (North entry) | D6: =IF(_xlfn.MAXIFS('Inspection History'!$A$6:$A$20000,'Inspection History'!$B$6:$B$20000,$A6,'Inspection History'!$C$6:$C$20000,"Monthly Test",'Inspection History'!$D$6:$D$20000,"Pass")=0,"",_xlfn.MAXIFS('Inspection History'!$A$6:$A$20000,'Inspection History'!$B$6:$B$20000,$A6,'Inspection History'!$C$6:$C$20000,"Monthly Test",'Inspection History'!$D$6:$D$20000,"Pass")) -> 46301 | E6: =IF($D6="","",$D6+Intervals!$C$7) -> 46331 | F6: =IF(_xlfn.MAXIFS('Inspection History'!$A$6:$A$20000,'Inspection History'!$B$6:$B$20000,$A6,'Inspection History'!$C$6:$C$20000,"Annual Test",'Inspection History'!$D$6:$D$20000,"Pass")=0,"",_xlfn.MAXIFS('Inspection History'!$A$6:$A$20000,'Inspection History'!$B$6:$B$20000,$A6,'Inspection History'!$C$6:$C$20000,"Annual Test",'Inspection History'!$D$6:$D$20000,"Pass")) -> 46071 | G6: =IF($F6="","",EDATE($F6,Intervals!$C$8)) -> 46436 | H6: =IF(COUNT($E6,$G6)=0,"—",IF(MIN($E6,$G6)=$E6,"Monthly function test","Annual 90-minute test")) -> Monthly function test | I6: =IF(COUNT($E6,$G6)=0,"",MIN($E6,$G6)-TODAY()) -> 10 | J6: =IF($I6="","NOT LOGGED",IF($I6<=0,"OVERDUE",IF($I6<=Intervals!$C$26,"DUE SOON","OK"))) -> OK | L6: =IF($D6="","",IF(SUMPRODUCT(MAX(('Inspection History'!$B$6:$B$20000=$A6)*('Inspection History'!$C$6:$C$20000="Monthly Test")*('Inspection History'!$D$6:$D$20000="Pass")*('Inspection History'!$A$6:$A$20000=$D6)*ROW('Inspection History'!$A$6:$A$20000)))=0,"",INDEX('Inspection History'!$E:$E,SUMPRODUCT(MAX(('Inspection History'!$B$6:$B$20000=$A6)*('Inspection History'!$C$6:$C$20000="Monthly Test")*('Inspection History'!$D$6:$D$20000="Pass")*('Inspection History'!$A$6:$A$20000=$D6)*ROW('Inspection History'!$A$6:$A$20000))))&""))
A7: EL2 | B7: EL2 | C7: Admin Desk | D7: =IF(_xlfn.MAXIFS('Inspection History'!$A$6:$A$20000,'Inspection History'!$B$6:$B$20000,$A7,'Inspection History'!$C$6:$C$20000,"Monthly Test",'Inspection History'!$D$6:$D$20000,"Pass")=0,"",_xlfn.MAXIFS('Inspection History'!$A$6:$A$20000,'Inspection History'!$B$6:$B$20000,$A7,'Inspection History'!$C$6:$C$20000,"Monthly Test",'Inspection History'!$D$6:$D$20000,"Pass")) -> 46301 | E7: =IF($D7="","",$D7+Intervals!$C$7) -> 46331 | F7: =IF(_xlfn.MAXIFS('Inspection History'!$A$6:$A$20000,'Inspection History'!$B$6:$B$20000,$A7,'Inspection History'!$C$6:$C$20000,"Annual Test",'Inspection History'!$D$6:$D$20000,"Pass")=0,"",_xlfn.MAXIFS('Inspection History'!$A$6:$A$20000,'Inspection History'!$B$6:$B$20000,$A7,'Inspection History'!$C$6:$C$20000,"Annual Test",'Inspection History'!$D$6:$D$20000,"Pass")) -> 46071 | G7: =IF($F7="","",EDATE($F7,Intervals!$C$8)) -> 46436 | H7: =IF(COUNT($E7,$G7)=0,"—",IF(MIN($E7,$G7)=$E7,"Monthly function test","Annual 90-minute test")) -> Monthly function test | I7: =IF(COUNT($E7,$G7)=0,"",MIN($E7,$G7)-TODAY()) -> 10 | J7: =IF($I7="","NOT LOGGED",IF($I7<=0,"OVERDUE",IF($I7<=Intervals!$C$26,"DUE SOON","OK"))) -> OK | L7: =IF($D7="","",IF(SUMPRODUCT(MAX(('Inspection History'!$B$6:$B$20000=$A7)*('Inspection History'!$C$6:$C$20000="Monthly Test")*('Inspection History'!$D$6:$D$20000="Pass")*('Inspection History'!$A$6:$A$20000=$D7)*ROW('Inspection History'!$A$6:$A$20000)))=0,"",INDEX('Inspection History'!$E:$E,SUMPRODUCT(MAX(('Inspection History'!$B$6:$B$20000=$A7)*('Inspection History'!$C$6:$C$20000="Monthly Test")*('Inspection History'!$D$6:$D$20000="Pass")*('Inspection History'!$A$6:$A$20000=$D7)*ROW('Inspection History'!$A$6:$A$20000))))&""))
A8: EL3 | B8: EL3 | C8: Admin Desk / Visitors Office | D8: =IF(_xlfn.MAXIFS('Inspection History'!$A$6:$A$20000,'Inspection History'!$B$6:$B$20000,$A8,'Inspection History'!$C$6:$C$20000,"Monthly Test",'Inspection History'!$D$6:$D$20000,"Pass")=0,"",_xlfn.MAXIFS('Inspection History'!$A$6:$A$20000,'Inspection History'!$B$6:$B$20000,$A8,'Inspection History'!$C$6:$C$20000,"Monthly Test",'Inspection History'!$D$6:$D$20000,"Pass")) -> 46301 | E8: =IF($D8="","",$D8+Intervals!$C$7) -> 46331 | F8: =IF(_xlfn.MAXIFS('Inspection History'!$A$6:$A$20000,'Inspection History'!$B$6:$B$20000,$A8,'Inspection History'!$C$6:$C$20000,"Annual Test",'Inspection History'!$D$6:$D$20000,"Pass")=0,"",_xlfn.MAXIFS('Inspection History'!$A$6:$A$20000,'Inspection History'!$B$6:$B$20000,$A8,'Inspection History'!$C$6:$C$20000,"Annual Test",'Inspection History'!$D$6:$D$20000,"Pass")) -> 46071 | G8: =IF($F8="","",EDATE($F8,Intervals!$C$8)) -> 46436 | H8: =IF(COUNT($E8,$G8)=0,"—",IF(MIN($E8,$G8)=$E8,"Monthly function test","Annual 90-minute test")) -> Monthly function test | I8: =IF(COUNT($E8,$G8)=0,"",MIN($E8,$G8)-TODAY()) -> 10 | J8: =IF($I8="","NOT LOGGED",IF($I8<=0,"OVERDUE",IF($I8<=Intervals!$C$26,"DUE SOON","OK"))) -> OK | L8: =IF($D8="","",IF(SUMPRODUCT(MAX(('Inspection History'!$B$6:$B$20000=$A8)*('Inspection History'!$C$6:$C$20000="Monthly Test")*('Inspection History'!$D$6:$D$20000="Pass")*('Inspection History'!$A$6:$A$20000=$D8)*ROW('Inspection History'!$A$6:$A$20000)))=0,"",INDEX('Inspection History'!$E:$E,SUMPRODUCT(MAX(('Inspection History'!$B$6:$B$20000=$A8)*('Inspection History'!$C$6:$C$20000="Monthly Test")*('Inspection History'!$D$6:$D$20000="Pass")*('Inspection History'!$A$6:$A$20000=$D8)*ROW('Inspection History'!$A$6:$A$20000))))&""))
A9: EL4 | B9: NEW | C9: Office 2 / Office 3 corridor | D9: =IF(_xlfn.MAXIFS('Inspection History'!$A$6:$A$20000,'Inspection History'!$B$6:$B$20000,$A9,'Inspection History'!$C$6:$C$20000,"Monthly Test",'Inspection History'!$D$6:$D$20000,"Pass")=0,"",_xlfn.MAXIFS('Inspection History'!$A$6:$A$20000,'Inspection History'!$B$6:$B$20000,$A9,'Inspection History'!$C$6:$C$20000,"Monthly Test",'Inspection History'!$D$6:$D$20000,"Pass")) -> 46301 | E9: =IF($D9="","",$D9+Intervals!$C$7) -> 46331 | F9: =IF(_xlfn.MAXIFS('Inspection History'!$A$6:$A$20000,'Inspection History'!$B$6:$B$20000,$A9,'Inspection History'!$C$6:$C$20000,"Annual Test",'Inspection History'!$D$6:$D$20000,"Pass")=0,"",_xlfn.MAXIFS('Inspection History'!$A$6:$A$20000,'Inspection History'!$B$6:$B$20000,$A9,'Inspection History'!$C$6:$C$20000,"Annual Test",'Inspection History'!$D$6:$D$20000,"Pass")) -> 46071 | G9: =IF($F9="","",EDATE($F9,Intervals!$C$8)) -> 46436 | H9: =IF(COUNT($E9,$G9)=0,"—",IF(MIN($E9,$G9)=$E9,"Monthly function test","Annual 90-minute test")) -> Monthly function test | I9: =IF(COUNT($E9,$G9)=0,"",MIN($E9,$G9)-TODAY()) -> 10 | J9: =IF($I9="","NOT LOGGED",IF($I9<=0,"OVERDUE",IF($I9<=Intervals!$C$26,"DUE SOON","OK"))) -> OK | L9: =IF($D9="","",IF(SUMPRODUCT(MAX(('Inspection History'!$B$6:$B$20000=$A9)*('Inspection History'!$C$6:$C$20000="Monthly Test")*('Inspection History'!$D$6:$D$20000="Pass")*('Inspection History'!$A$6:$A$20000=$D9)*ROW('Inspection History'!$A$6:$A$20000)))=0,"",INDEX('Inspection History'!$E:$E,SUMPRODUCT(MAX(('Inspection History'!$B$6:$B$20000=$A9)*('Inspection History'!$C$6:$C$20000="Monthly Test")*('Inspection History'!$D$6:$D$20000="Pass")*('Inspection History'!$A$6:$A$20000=$D9)*ROW('Inspection History'!$A$6:$A$20000))))&""))
